Workbook

Sheet README
B2: GCC Cost Model — Marston & Vale (5-year run)
B4: Baseline: current UK/IE loaded cost for in-scope roles | Scenarios: Bengaluru-only, Hyderabad-only, Pune-only, and Recommended (Blr + Pune)
B6: Prepared by | C6: Rhea Nathan
B7: Version | C7: v3.0
B8: Last updated | C8: 05 Oct 2026
B9: FX assumption | C9: 1 GBP = 105 INR | 1 USD = 83.5 INR
B10: Inflation assumption | C10: 8% India salary inflation p.a.; 3.5% UK; 2% infra
B11: Attrition assumption | C11: Y1: 18%; Y2: 16%; Y3+: 14% steady-state (retention design assumed)
B12: Confidentiality | C12: Client Confidential
B14: Colour convention
B15: Blue text | C15: Hardcoded inputs / assumptions the user can change
B16: Black text | C16: Formulas / calculations
B17: Green text | C17: Links pulled from other sheets
B18: Yellow fill | C18: Key assumption — flagged for attention
B20: Tab guide
B21: Assumptions | C21: All key input parameters — inflation, ratios, ramp curves, benefits loads
B22: HC Ramp | C22: Headcount ramp Y1→Y5 by tower and city
B23: Core Talent Cost | C23: Fully-loaded talent cost by year and scenario
B24: Infra & Facilities | C24: Real estate, fit-out, utilities, transport, F&B
B25: Back-office (Ratios) | C25: Enabling function staffing using x:1 ratios
B26: Total Cost Summary | C26: 5-year cost by scenario + savings vs UK baseline
B27: Scenario Comparison | C27: Side-by-side scorecard of the 4 scenarios

Sheet Assumptions
B2: Key assumptions (editable inputs shown in blue)
B4: MACRO
B5: Parameter | C5: Value | D5: Unit
B6: GBP → INR | C6: 105 | D6: INR / GBP
B7: USD → INR | C7: 83.5 | D7: INR / USD
B8: India salary inflation | C8: 0.08 | D8: % p.a.
B9: UK salary inflation | C9: 0.035 | D9: % p.a.
B10: Infra inflation | C10: 0.02 | D10: % p.a.
B12: COMP LOADS
B13: Parameter | C13: Value | D13: Notes
B14: Benefits load | C14: 0.15 | D14: medical, insurance, learning, wellness
B15: Variable pay (target) | C15: 0.12 | D15: % of base
B16: Statutory contribution | C16: 0.02 | D16: PF, gratuity, LWF
B17: Attrition Y1 | C17: 0.18 | D17: voluntary
B18: Attrition Y2 | C18: 0.16 | D18: voluntary
B19: Attrition steady-state | C19: 0.14 | D19: Y3+
B20: Backfill cost premium | C20: 0.08 | D20: % of loaded comp
B22: BACK-OFFICE RATIOS (Enabler : Core FTE)
B23: Function | C23: Steady-state (1 per) | D23: Ramp Y1 (1 per) | E23: Avg loaded cost (INR L)
B24: HR Ops (generalist + TA) | C24: 25 | D24: 18 | E24: 14
B25: Finance Ops (AP/GL/Controllership) | C25: 40 | D25: 30 | E25: 15
B26: IT Support / DevEx | C26: 75 | D26: 60 | E26: 16
B27: Facilities / Admin (managed) | C27: 100 | D27: 80 | E27: 9
B28: Site Leadership + PMO | C28: 60 | D28: 40 | E28: 42
B30: INFRA & FACILITIES
B31: Parameter | C31: Bengaluru | D31: Hyderabad | E31: Pune | F31: Unit
B32: Rent (Grade A, warm shell) | C32: 112 | D32: 72 | E32: 82 | F32: INR / sqft / mo
B33: Sqft per FTE | C33: 65 | D33: 65 | E33: 65 | F33: sqft
B34: Fit-out capex (per sqft) | C34: 3800 | D34: 3200 | E34: 3400 | F34: INR
B35: Fit-out amortization | C35: 7 | D35: 7 | E35: 7 | F35: years
B36: Utilities per FTE / mo | C36: 3200 | D36: 2600 | E36: 2900 | F36: INR
B37: Transport per FTE / mo | C37: 4800 | D37: 3800 | E37: 4200 | F37: INR
B38: F&B / cafeteria per FTE / mo | C38: 2400 | D38: 2000 | E38: 2200 | F38: INR
B39: Security + insurance per FTE / mo | C39: 1600 | D39: 1400 | E39: 1500 | F39: INR
B41: UK / IE BASELINE (like-for-like loaded cost per FTE)
B42: Function | C42: Avg loaded cost (GBP) | D42: In INR Lakh
B43: Product / Platform Eng. | C43: 82000 | D43: =ROUND(C43*$C$6/100000,1) -> 86.1
B44: Data / ML / Analytics | C44: 95000 | D44: =ROUND(C44*$C$6/100000,1) -> 99.8
B45: Cloud & Cybersecurity | C45: 88000 | D45: =ROUND(C45*$C$6/100000,1) -> 92.4
B46: Finance Ops | C46: 52000 | D46: =ROUND(C46*$C$6/100000,1) -> 54.6
...

Sheet HC Ramp
B2: Headcount ramp — Recommended scenario (Bengaluru + Pune)
B3: Same total headcount applied to single-city scenarios; only the city allocation changes.
B5: Tower | C5: City (recommended) | D5: Year 1 | E5: Year 2 | F5: Year 3 | G5: Year 4 | H5: Year 5
B6: Product / Platform Eng. | C6: Bengaluru | D6: 60 | E6: 130 | F6: 200 | G6: 220 | H6: 240
B7: Data / ML / Analytics | C7: Bengaluru | D7: 30 | E7: 65 | F7: 98 | G7: 110 | H7: 120
B8: Cloud & Cybersecurity | C8: Bengaluru | D8: 20 | E8: 40 | F8: 65 | G8: 72 | H8: 80
B9: Customer Support | C9: Bengaluru | D9: 35 | E9: 70 | F9: 90 | G9: 100 | H9: 110
B10: Site Leadership + PMO | C10: Bengaluru | D10: 20 | E10: 45 | F10: 60 | G10: 65 | H10: 70
B11: HR Ops (site) | C11: Bengaluru | D11: 8 | E11: 16 | F11: 24 | G11: 26 | H11: 28
B12: Finance Ops | C12: Pune | D12: 0 | E12: 55 | F12: 114 | G12: 130 | H12: 145
B13: HR Ops (CoE) | C13: Pune | D13: 0 | E13: 18 | F13: 43 | G13: 48 | H13: 52
B14: TOTAL | D14: =SUM(D6:D13) -> 173 | E14: =SUM(E6:E13) -> 439 | F14: =SUM(F6:F13) -> 694 | G14: =SUM(G6:G13) -> 771 | H14: =SUM(H6:H13) -> 845
B16: By city
B17: Bengaluru | D17: =SUMIF($C$6:$C$13,"Bengaluru",D$6:D$13) -> 173 | E17: =SUMIF($C$6:$C$13,"Bengaluru",E$6:E$13) -> 366 | F17: =SUMIF($C$6:$C$13,"Bengaluru",F$6:F$13) -> 537 | G17: =SUMIF($C$6:$C$13,"Bengaluru",G$6:G$13) -> 593 | H17: =SUMIF($C$6:$C$13,"Bengaluru",H$6:H$13) -> 648
B18: Pune | D18: =SUMIF($C$6:$C$13,"Pune",D$6:D$13) -> 0 | E18: =SUMIF($C$6:$C$13,"Pune",E$6:E$13) -> 73 | F18: =SUMIF($C$6:$C$13,"Pune",F$6:F$13) -> 157 | G18: =SUMIF($C$6:$C$13,"Pune",G$6:G$13) -> 178 | H18: =SUMIF($C$6:$C$13,"Pune",H$6:H$13) -> 197

Sheet Core Talent Cost
B2: Core talent cost — INR Crore per year, by tower
B3: Cost = HC × loaded cost per FTE × (1 + inflation)^(year-1). Loaded cost per FTE is a blended L1-L4 weighted average from Salary Benchmark.
B5: Tower | C5: Loaded cost / FTE (INR L, Y1) | D5: Year 1 | E5: Year 2 | F5: Year 3 | G5: Year 4 | H5: Year 5
B6: Product / Platform Eng. | C6: 24.5 | D6: =('HC Ramp'!D6)*$C6*(1+Assumptions!$C$8)^(1-1)/100 -> 14.7 | E6: =('HC Ramp'!E6)*$C6*(1+Assumptions!$C$8)^(2-1)/100 -> 34.398 | F6: =('HC Ramp'!F6)*$C6*(1+Assumptions!$C$8)^(3-1)/100 -> 57.1536 | G6: =('HC Ramp'!G6)*$C6*(1+Assumptions!$C$8)^(4-1)/100 -> 67.898477 | H6: =('HC Ramp'!H6)*$C6*(1+Assumptions!$C$8)^(5-1)/100 -> 79.996751
B7: Data / ML / Analytics | C7: 29.2 | D7: =('HC Ramp'!D7)*$C7*(1+Assumptions!$C$8)^(1-1)/100 -> 8.76 | E7: =('HC Ramp'!E7)*$C7*(1+Assumptions!$C$8)^(2-1)/100 -> 20.4984 | F7: =('HC Ramp'!F7)*$C7*(1+Assumptions!$C$8)^(3-1)/100 -> 33.377702 | G7: =('HC Ramp'!G7)*$C7*(1+Assumptions!$C$8)^(4-1)/100 -> 40.461949 | H7: =('HC Ramp'!H7)*$C7*(1+Assumptions!$C$8)^(5-1)/100 -> 47.671533
B8: Cloud & Cybersecurity | C8: 26.4 | D8: =('HC Ramp'!D8)*$C8*(1+Assumptions!$C$8)^(1-1)/100 -> 5.28 | E8: =('HC Ramp'!E8)*$C8*(1+Assumptions!$C$8)^(2-1)/100 -> 11.4048 | F8: =('HC Ramp'!F8)*$C8*(1+Assumptions!$C$8)^(3-1)/100 -> 20.015424 | G8: =('HC Ramp'!G8)*$C8*(1+Assumptions!$C$8)^(4-1)/100 -> 23.944606 | H8: =('HC Ramp'!H8)*$C8*(1+Assumptions!$C$8)^(5-1)/100 -> 28.733527
B9: Customer Support | C9: 10.2 | D9: =('HC Ramp'!D9)*$C9*(1+Assumptions!$C$8)^(1-1)/100 -> 3.57 | E9: =('HC Ramp'!E9)*$C9*(1+Assumptions!$C$8)^(2-1)/100 -> 7.7112 | F9: =('HC Ramp'!F9)*$C9*(1+Assumptions!$C$8)^(3-1)/100 -> 10.707552 | G9: =('HC Ramp'!G9)*$C9*(1+Assumptions!$C$8)^(4-1)/100 -> 12.849062 | H9: =('HC Ramp'!H9)*$C9*(1+Assumptions!$C$8)^(5-1)/100 -> 15.264686
B10: Site Leadership + PMO | C10: 38 | D10: =('HC Ramp'!D10)*$C10*(1+Assumptions!$C$8)^(1-1)/100 -> 7.6 | E10: =('HC Ramp'!E10)*$C10*(1+Assumptions!$C$8)^(2-1)/100 -> 18.468 | F10: =('HC Ramp'!F10)*$C10*(1+Assumptions!$C$8)^(3-1)/100 -> 26.59392 | G10: =('HC Ramp'!G10)*$C10*(1+Assumptions!$C$8)^(4-1)/100 -> 31.114886 | H10: =('HC Ramp'!H10)*$C10*(1+Assumptions!$C$8)^(5-1)/100 -> 36.189006
B11: HR Ops (site) | C11: 13.6 | D11: =('HC Ramp'!D11)*$C11*(1+Assumptions!$C$8)^(1-1)/100 -> 1.088 | E11: =('HC Ramp'!E11)*$C11*(1+Assumptions!$C$8)^(2-1)/100 -> 2.35008 | F11: =('HC Ramp'!F11)*$C11*(1+Assumptions!$C$8)^(3-1)/100 -> 3.8071296 | G11: =('HC Ramp'!G11)*$C11*(1+Assumptions!$C$8)^(4-1)/100 -> 4.4543416 | H11: =('HC Ramp'!H11)*$C11*(1+Assumptions!$C$8)^(5-1)/100 -> 5.180742
B12: Finance Ops | C12: 13.8 | D12: =('HC Ramp'!D12)*$C12*(1+Assumptions!$C$8)^(1-1)/100 -> 0 | E12: =('HC Ramp'!E12)*$C12*(1+Assumptions!$C$8)^(2-1)/100 -> 8.1972 | F12: =('HC Ramp'!F12)*$C12*(1+Assumptions!$C$8)^(3-1)/100 -> 18.349805 | G12: =('HC Ramp'!G12)*$C12*(1+Assumptions!$C$8)^(4-1)/100 -> 22.599233 | H12: =('HC Ramp'!H12)*$C12*(1+Assumptions!$C$8)^(5-1)/100 -> 27.223384
B13: HR Ops (CoE) | C13: 12.8 | D13: =('HC Ramp'!D13)*$C13*(1+Assumptions!$C$8)^(1-1)/100 -> 0 | E13: =('HC Ramp'!E13)*$C13*(1+Assumptions!$C$8)^(2-1)/100 -> 2.48832 | F13: =('HC Ramp'!F13)*$C13*(1+Assumptions!$C$8)^(3-1)/100 -> 6.4198656 | G13: =('HC Ramp'!G13)*$C13*(1+Assumptions!$C$8)^(4-1)/100 -> 7.7396705 | H13: =('HC Ramp'!H13)*$C13*(1+Assumptions!$C$8)^(5-1)/100 -> 9.0554145
B14: TOTAL Core Talent (Crore) | D14: =SUM(D6:D13) -> 40.998 | E14: =SUM(E6:E13) -> 105.516 | F14: =SUM(F6:F13) -> 176.425 | G14: =SUM(G6:G13) -> 211.06223 | H14: =SUM(H6:H13) -> 249.31504
B15: In GBP million (÷ 10.5) | D15: =D14*10/Assumptions!$C$6 -> 3.9045714 | E15: =E14*10/Assumptions!$C$6 -> 10.049143 | F15: =F14*10/Assumptions!$C$6 -> 16.802381 | G15: =G14*10/Assumptions!$C$6 -> 20.101164 | H15: =H14*10/Assumptions!$C$6 -> 23.74429

Sheet Infra & Facilities
B2: Infrastructure & facilities cost (INR Crore per year)
B3: Recommended scenario — Bengaluru primary + Pune spoke. Amortization straight-line over 7 years.
B5: Cost head | C5: City | D5: Year 1 | E5: Year 2 | F5: Year 3 | G5: Year 4 | H5: Year 5
B6: Rent | C6: Bengaluru | D6: ='HC Ramp'!D16*INDEX(Assumptions!C:C,MATCH("Sqft per FTE",Assumptions!$B:$B,0))*INDEX(Assumptions!C:C,MATCH("Rent (Grade A, warm shell)",Assumptions!$B:$B,0))*12*(1+Assumptions!$C$10)^(1-1)/10000000 -> 0 | E6: ='HC Ramp'!E16*INDEX(Assumptions!C:C,MATCH("Sqft per FTE",Assumptions!$B:$B,0))*INDEX(Assumptions!C:C,MATCH("Rent (Grade A, warm shell)",Assumptions!$B:$B,0))*12*(1+Assumptions!$C$10)^(2-1)/10000000 -> 0 | F6: ='HC Ramp'!F16*INDEX(Assumptions!C:C,MATCH("Sqft per FTE",Assumptions!$B:$B,0))*INDEX(Assumptions!C:C,MATCH("Rent (Grade A, warm shell)",Assumptions!$B:$B,0))*12*(1+Assumptions!$C$10)^(3-1)/10000000 -> 0 | G6: ='HC Ramp'!G16*INDEX(Assumptions!C:C,MATCH("Sqft per FTE",Assumptions!$B:$B,0))*INDEX(Assumptions!C:C,MATCH("Rent (Grade A, warm shell)",Assumptions!$B:$B,0))*12*(1+Assumptions!$C$10)^(4-1)/10000000 -> 0 | H6: ='HC Ramp'!H16*INDEX(Assumptions!C:C,MATCH("Sqft per FTE",Assumptions!$B:$B,0))*INDEX(Assumptions!C:C,MATCH("Rent (Grade A, warm shell)",Assumptions!$B:$B,0))*12*(1+Assumptions!$C$10)^(5-1)/10000000 -> 0
B7: Rent | C7: Pune | D7: ='HC Ramp'!D17*INDEX(Assumptions!E:E,MATCH("Sqft per FTE",Assumptions!$B:$B,0))*INDEX(Assumptions!E:E,MATCH("Rent (Grade A, warm shell)",Assumptions!$B:$B,0))*12*(1+Assumptions!$C$10)^(1-1)/10000000 -> 1.106508 | E7: ='HC Ramp'!E17*INDEX(Assumptions!E:E,MATCH("Sqft per FTE",Assumptions!$B:$B,0))*INDEX(Assumptions!E:E,MATCH("Rent (Grade A, warm shell)",Assumptions!$B:$B,0))*12*(1+Assumptions!$C$10)^(2-1)/10000000 -> 2.3877547 | F7: ='HC Ramp'!F17*INDEX(Assumptions!E:E,MATCH("Sqft per FTE",Assumptions!$B:$B,0))*INDEX(Assumptions!E:E,MATCH("Rent (Grade A, warm shell)",Assumptions!$B:$B,0))*12*(1+Assumptions!$C$10)^(3-1)/10000000 -> 3.5734119 | G7: ='HC Ramp'!G17*INDEX(Assumptions!E:E,MATCH("Sqft per FTE",Assumptions!$B:$B,0))*INDEX(Assumptions!E:E,MATCH("Rent (Grade A, warm shell)",Assumptions!$B:$B,0))*12*(1+Assumptions!$C$10)^(4-1)/10000000 -> 4.0249794 | H7: ='HC Ramp'!H17*INDEX(Assumptions!E:E,MATCH("Sqft per FTE",Assumptions!$B:$B,0))*INDEX(Assumptions!E:E,MATCH("Rent (Grade A, warm shell)",Assumptions!$B:$B,0))*12*(1+Assumptions!$C$10)^(5-1)/10000000 -> 4.486257
B8: Utilities | C8: Bengaluru | D8: ='HC Ramp'!D16*INDEX(Assumptions!C:C,MATCH("Utilities per FTE / mo",Assumptions!$B:$B,0))*12*(1+Assumptions!$C$10)^(1-1)/10000000 -> 0 | E8: ='HC Ramp'!E16*INDEX(Assumptions!C:C,MATCH("Utilities per FTE / mo",Assumptions!$B:$B,0))*12*(1+Assumptions!$C$10)^(2-1)/10000000 -> 0 | F8: ='HC Ramp'!F16*INDEX(Assumptions!C:C,MATCH("Utilities per FTE / mo",Assumptions!$B:$B,0))*12*(1+Assumptions!$C$10)^(3-1)/10000000 -> 0 | G8: ='HC Ramp'!G16*INDEX(Assumptions!C:C,MATCH("Utilities per FTE / mo",Assumptions!$B:$B,0))*12*(1+Assumptions!$C$10)^(4-1)/10000000 -> 0 | H8: ='HC Ramp'!H16*INDEX(Assumptions!C:C,MATCH("Utilities per FTE / mo",Assumptions!$B:$B,0))*12*(1+Assumptions!$C$10)^(5-1)/10000000 -> 0
B9: Utilities | C9: Pune | D9: ='HC Ramp'!D17*INDEX(Assumptions!E:E,MATCH("Utilities per FTE / mo",Assumptions!$B:$B,0))*12*(1+Assumptions!$C$10)^(1-1)/10000000 -> 0.60204 | E9: ='HC Ramp'!E17*INDEX(Assumptions!E:E,MATCH("Utilities per FTE / mo",Assumptions!$B:$B,0))*12*(1+Assumptions!$C$10)^(2-1)/10000000 -> 1.2991536 | F9: ='HC Ramp'!F17*INDEX(Assumptions!E:E,MATCH("Utilities per FTE / mo",Assumptions!$B:$B,0))*12*(1+Assumptions!$C$10)^(3-1)/10000000 -> 1.9442579 | G9: ='HC Ramp'!G17*INDEX(Assumptions!E:E,MATCH("Utilities per FTE / mo",Assumptions!$B:$B,0))*12*(1+Assumptions!$C$10)^(4-1)/10000000 -> 2.1899513 | H9: ='HC Ramp'!H17*INDEX(Assumptions!E:E,MATCH("Utilities per FTE / mo",Assumptions!$B:$B,0))*12*(1+Assumptions!$C$10)^(5-1)/10000000 -> 2.4409278
B10: Transport | C10: Bengaluru | D10: ='HC Ramp'!D16*INDEX(Assumptions!C:C,MATCH("Transport per FTE / mo",Assumptions!$B:$B,0))*12*(1+Assumptions!$C$10)^(1-1)/10000000 -> 0 | E10: ='HC Ramp'!E16*INDEX(Assumptions!C:C,MATCH("Transport per FTE / mo",Assumptions!$B:$B,0))*12*(1+Assumptions!$C$10)^(2-1)/10000000 -> 0 | F10: ='HC Ramp'!F16*INDEX(Assumptions!C:C,MATCH("Transport per FTE / mo",Assumptions!$B:$B,0))*12*(1+Assumptions!$C$10)^(3-1)/10000000 -> 0 | G10: ='HC Ramp'!G16*INDEX(Assumptions!C:C,MATCH("Transport per FTE / mo",Assumptions!$B:$B,0))*12*(1+Assumptions!$C$10)^(4-1)/10000000 -> 0 | H10: ='HC Ramp'!H16*INDEX(Assumptions!C:C,MATCH("Transport per FTE / mo",Assumptions!$B:$B,0))*12*(1+Assumptions!$C$10)^(5-1)/10000000 -> 0
B11: Transport | C11: Pune | D11: ='HC Ramp'!D17*INDEX(Assumptions!E:E,MATCH("Transport per FTE / mo",Assumptions!$B:$B,0))*12*(1+Assumptions!$C$10)^(1-1)/10000000 -> 0.87192 | E11: ='HC Ramp'!E17*INDEX(Assumptions!E:E,MATCH("Transport per FTE / mo",Assumptions!$B:$B,0))*12*(1+Assumptions!$C$10)^(2-1)/10000000 -> 1.8815328 | F11: ='HC Ramp'!F17*INDEX(Assumptions!E:E,MATCH("Transport per FTE / mo",Assumptions!$B:$B,0))*12*(1+Assumptions!$C$10)^(3-1)/10000000 -> 2.8158218 | G11: ='HC Ramp'!G17*INDEX(Assumptions!E:E,MATCH("Transport per FTE / mo",Assumptions!$B:$B,0))*12*(1+Assumptions!$C$10)^(4-1)/10000000 -> 3.1716536 | H11: ='HC Ramp'!H17*INDEX(Assumptions!E:E,MATCH("Transport per FTE / mo",Assumptions!$B:$B,0))*12*(1+Assumptions!$C$10)^(5-1)/10000000 -> 3.5351368
B12: F&B | C12: Bengaluru | D12: ='HC Ramp'!D16*INDEX(Assumptions!C:C,MATCH("F&B / cafeteria per FTE / mo",Assumptions!$B:$B,0))*12*(1+Assumptions!$C$10)^(1-1)/10000000 -> 0 | E12: ='HC Ramp'!E16*INDEX(Assumptions!C:C,MATCH("F&B / cafeteria per FTE / mo",Assumptions!$B:$B,0))*12*(1+Assumptions!$C$10)^(2-1)/10000000 -> 0 | F12: ='HC Ramp'!F16*INDEX(Assumptions!C:C,MATCH("F&B / cafeteria per FTE / mo",Assumptions!$B:$B,0))*12*(1+Assumptions!$C$10)^(3-1)/10000000 -> 0 | G12: ='HC Ramp'!G16*INDEX(Assumptions!C:C,MATCH("F&B / cafeteria per FTE / mo",Assumptions!$B:$B,0))*12*(1+Assumptions!$C$10)^(4-1)/10000000 -> 0 | H12: ='HC Ramp'!H16*INDEX(Assumptions!C:C,MATCH("F&B / cafeteria per FTE / mo",Assumptions!$B:$B,0))*12*(1+Assumptions!$C$10)^(5-1)/10000000 -> 0
B13: F&B | C13: Pune | D13: ='HC Ramp'!D17*INDEX(Assumptions!E:E,MATCH("F&B / cafeteria per FTE / mo",Assumptions!$B:$B,0))*12*(1+Assumptions!$C$10)^(1-1)/10000000 -> 0.45672 | E13: ='HC Ramp'!E17*INDEX(Assumptions!E:E,MATCH("F&B / cafeteria per FTE / mo",Assumptions!$B:$B,0))*12*(1+Assumptions!$C$10)^(2-1)/10000000 -> 0.9855648 | F13: ='HC Ramp'!F17*INDEX(Assumptions!E:E,MATCH("F&B / cafeteria per FTE / mo",Assumptions!$B:$B,0))*12*(1+Assumptions!$C$10)^(3-1)/10000000 -> 1.4749543 | G13: ='HC Ramp'!G17*INDEX(Assumptions!E:E,MATCH("F&B / cafeteria per FTE / mo",Assumptions!$B:$B,0))*12*(1+Assumptions!$C$10)^(4-1)/10000000 -> 1.6613423 | H13: ='HC Ramp'!H17*INDEX(Assumptions!E:E,MATCH("F&B / cafeteria per FTE / mo",Assumptions!$B:$B,0))*12*(1+Assumptions!$C$10)^(5-1)/10000000 -> 1.8517383
B14: Security+Ins | C14: Bengaluru | D14: ='HC Ramp'!D16*INDEX(Assumptions!C:C,MATCH("Security + insurance per FTE / mo",Assumptions!$B:$B,0))*12*(1+Assumptions!$C$10)^(1-1)/10000000 -> 0 | E14: ='HC Ramp'!E16*INDEX(Assumptions!C:C,MATCH("Security + insurance per FTE / mo",Assumptions!$B:$B,0))*12*(1+Assumptions!$C$10)^(2-1)/10000000 -> 0 | F14: ='HC Ramp'!F16*INDEX(Assumptions!C:C,MATCH("Security + insurance per FTE / mo",Assumptions!$B:$B,0))*12*(1+Assumptions!$C$10)^(3-1)/10000000 -> 0 | G14: ='HC Ramp'!G16*INDEX(Assumptions!C:C,MATCH("Security + insurance per FTE / mo",Assumptions!$B:$B,0))*12*(1+Assumptions!$C$10)^(4-1)/10000000 -> 0 | H14: ='HC Ramp'!H16*INDEX(Assumptions!C:C,MATCH("Security + insurance per FTE / mo",Assumptions!$B:$B,0))*12*(1+Assumptions!$C$10)^(5-1)/10000000 -> 0
B15: Security+Ins | C15: Pune | D15: ='HC Ramp'!D17*INDEX(Assumptions!E:E,MATCH("Security + insurance per FTE / mo",Assumptions!$B:$B,0))*12*(1+Assumptions!$C$10)^(1-1)/10000000 -> 0.3114 | E15: ='HC Ramp'!E17*INDEX(Assumptions!E:E,MATCH("Security + insurance per FTE / mo",Assumptions!$B:$B,0))*12*(1+Assumptions!$C$10)^(2-1)/10000000 -> 0.671976 | F15: ='HC Ramp'!F17*INDEX(Assumptions!E:E,MATCH("Security + insurance per FTE / mo",Assumptions!$B:$B,0))*12*(1+Assumptions!$C$10)^(3-1)/10000000 -> 1.0056506 | G15: ='HC Ramp'!G17*INDEX(Assumptions!E:E,MATCH("Security + insurance per FTE / mo",Assumptions!$B:$B,0))*12*(1+Assumptions!$C$10)^(4-1)/10000000 -> 1.1327334 | H15: ='HC Ramp'!H17*INDEX(Assumptions!E:E,MATCH("Security + insurance per FTE / mo",Assumptions!$B:$B,0))*12*(1+Assumptions!$C$10)^(5-1)/10000000 -> 1.2625489
B16: Fit-out amort | C16: Bengaluru | D16: ='HC Ramp'!D16*INDEX(Assumptions!C:C,MATCH("Sqft per FTE",Assumptions!$B:$B,0))*INDEX(Assumptions!C:C,MATCH("Fit-out capex (per sqft)",Assumptions!$B:$B,0))/INDEX(Assumptions!C:C,MATCH("Fit-out amortization",Assumptions!$B:$B,0))/10000000 -> 0 | E16: ='HC Ramp'!E16*INDEX(Assumptions!C:C,MATCH("Sqft per FTE",Assumptions!$B:$B,0))*INDEX(Assumptions!C:C,MATCH("Fit-out capex (per sqft)",Assumptions!$B:$B,0))/INDEX(Assumptions!C:C,MATCH("Fit-out amortization",Assumptions!$B:$B,0))/10000000 -> 0 | F16: ='HC Ramp'!F16*INDEX(Assumptions!C:C,MATCH("Sqft per FTE",Assumptions!$B:$B,0))*INDEX(Assumptions!C:C,MATCH("Fit-out capex (per sqft)",Assumptions!$B:$B,0))/INDEX(Assumptions!C:C,MATCH("Fit-out amortization",Assumptions!$B:$B,0))/10000000 -> 0 | G16: ='HC Ramp'!G16*INDEX(Assumptions!C:C,MATCH("Sqft per FTE",Assumptions!$B:$B,0))*INDEX(Assumptions!C:C,MATCH("Fit-out capex (per sqft)",Assumptions!$B:$B,0))/INDEX(Assumptions!C:C,MATCH("Fit-out amortization",Assumptions!$B:$B,0))/10000000 -> 0 | H16: ='HC Ramp'!H16*INDEX(Assumptions!C:C,MATCH("Sqft per FTE",Assumptions!$B:$B,0))*INDEX(Assumptions!C:C,MATCH("Fit-out capex (per sqft)",Assumptions!$B:$B,0))/INDEX(Assumptions!C:C,MATCH("Fit-out amortization",Assumptions!$B:$B,0))/10000000 -> 0
B17: Fit-out amort | C17: Pune | D17: ='HC Ramp'!D17*INDEX(Assumptions!E:E,MATCH("Sqft per FTE",Assumptions!$B:$B,0))*INDEX(Assumptions!E:E,MATCH("Fit-out capex (per sqft)",Assumptions!$B:$B,0))/INDEX(Assumptions!E:E,MATCH("Fit-out amortization",Assumptions!$B:$B,0))/10000000 -> 0.54618571 | E17: ='HC Ramp'!E17*INDEX(Assumptions!E:E,MATCH("Sqft per FTE",Assumptions!$B:$B,0))*INDEX(Assumptions!E:E,MATCH("Fit-out capex (per sqft)",Assumptions!$B:$B,0))/INDEX(Assumptions!E:E,MATCH("Fit-out amortization",Assumptions!$B:$B,0))/10000000 -> 1.1555143 | F17: ='HC Ramp'!F17*INDEX(Assumptions!E:E,MATCH("Sqft per FTE",Assumptions!$B:$B,0))*INDEX(Assumptions!E:E,MATCH("Fit-out capex (per sqft)",Assumptions!$B:$B,0))/INDEX(Assumptions!E:E,MATCH("Fit-out amortization",Assumptions!$B:$B,0))/10000000 -> 1.6953857 | G17: ='HC Ramp'!G17*INDEX(Assumptions!E:E,MATCH("Sqft per FTE",Assumptions!$B:$B,0))*INDEX(Assumptions!E:E,MATCH("Fit-out capex (per sqft)",Assumptions!$B:$B,0))/INDEX(Assumptions!E:E,MATCH("Fit-out amortization",Assumptions!$B:$B,0))/10000000 -> 1.8721857 | H17: ='HC Ramp'!H17*INDEX(Assumptions!E:E,MATCH("Sqft per FTE",Assumptions!$B:$B,0))*INDEX(Assumptions!E:E,MATCH("Fit-out capex (per sqft)",Assumptions!$B:$B,0))/INDEX(Assumptions!E:E,MATCH("Fit-out amortization",Assumptions!$B:$B,0))/10000000 -> 2.0458286
B18: TOTAL Infra (Crore) | D18: =SUM(D6:D17) -> 3.8947737 | E18: =SUM(E6:E17) -> 8.3814962 | F18: =SUM(F6:F17) -> 12.509482 | G18: =SUM(G6:G17) -> 14.052846 | H18: =SUM(H6:H17) -> 15.622437
B20: One-time Y1 setup (capex) | D20: =60000*INDEX(Assumptions!C:C,MATCH("Fit-out capex (per sqft)",Assumptions!$B:$B,0))/10000000 + 3 -> 25.8 | E20: =25000*INDEX(Assumptions!E:E,MATCH("Fit-out capex (per sqft)",Assumptions!$B:$B,0))/10000000 + 2 -> 10.5 | H20: 0 | I20: 0 | J20: 0

Sheet Back-office (Ratios)
B2: Back-office headcount & cost (using x:1 ratios)
B3: Ramp-up (Y1) ratios are hotter than steady-state to build plumbing before core teams arrive.
B5: Enabling function | C5: Ratio used | D5: Year 1 | E5: Year 2 | F5: Year 3 | G5: Year 4 | H5: Year 5
B6: HR Ops (generalist + TA) HC | C6: 1 : 25 (SS) | D6: =ROUNDUP('HC Ramp'!D14/INDEX(Assumptions!$D:$D,MATCH("HR Ops (generalist + TA)",Assumptions!$B:$B,0)),0) -> 10 | E6: =ROUNDUP('HC Ramp'!E14/INDEX(Assumptions!$C:$C,MATCH("HR Ops (generalist + TA)",Assumptions!$B:$B,0)),0) -> 18 | F6: =ROUNDUP('HC Ramp'!F14/INDEX(Assumptions!$C:$C,MATCH("HR Ops (generalist + TA)",Assumptions!$B:$B,0)),0) -> 28 | G6: =ROUNDUP('HC Ramp'!G14/INDEX(Assumptions!$C:$C,MATCH("HR Ops (generalist + TA)",Assumptions!$B:$B,0)),0) -> 31 | H6: =ROUNDUP('HC Ramp'!H14/INDEX(Assumptions!$C:$C,MATCH("HR Ops (generalist + TA)",Assumptions!$B:$B,0)),0) -> 34
B7: Finance Ops (AP/GL/Controllership) HC | C7: 1 : 25 (SS) | D7: =ROUNDUP('HC Ramp'!D14/INDEX(Assumptions!$D:$D,MATCH("Finance Ops (AP/GL/Controllership)",Assumptions!$B:$B,0)),0) -> 6 | E7: =ROUNDUP('HC Ramp'!E14/INDEX(Assumptions!$C:$C,MATCH("Finance Ops (AP/GL/Controllership)",Assumptions!$B:$B,0)),0) -> 11 | F7: =ROUNDUP('HC Ramp'!F14/INDEX(Assumptions!$C:$C,MATCH("Finance Ops (AP/GL/Controllership)",Assumptions!$B:$B,0)),0) -> 18 | G7: =ROUNDUP('HC Ramp'!G14/INDEX(Assumptions!$C:$C,MATCH("Finance Ops (AP/GL/Controllership)",Assumptions!$B:$B,0)),0) -> 20 | H7: =ROUNDUP('HC Ramp'!H14/INDEX(Assumptions!$C:$C,MATCH("Finance Ops (AP/GL/Controllership)",Assumptions!$B:$B,0)),0) -> 22
B8: IT Support / DevEx HC | C8: 1 : 25 (SS) | D8: =ROUNDUP('HC Ramp'!D14/INDEX(Assumptions!$D:$D,MATCH("IT Support / DevEx",Assumptions!$B:$B,0)),0) -> 3 | E8: =ROUNDUP('HC Ramp'!E14/INDEX(Assumptions!$C:$C,MATCH("IT Support / DevEx",Assumptions!$B:$B,0)),0) -> 6 | F8: =ROUNDUP('HC Ramp'!F14/INDEX(Assumptions!$C:$C,MATCH("IT Support / DevEx",Assumptions!$B:$B,0)),0) -> 10 | G8: =ROUNDUP('HC Ramp'!G14/INDEX(Assumptions!$C:$C,MATCH("IT Support / DevEx",Assumptions!$B:$B,0)),0) -> 11 | H8: =ROUNDUP('HC Ramp'!H14/INDEX(Assumptions!$C:$C,MATCH("IT Support / DevEx",Assumptions!$B:$B,0)),0) -> 12
B9: Facilities / Admin (managed) HC | C9: 1 : 25 (SS) | D9: =ROUNDUP('HC Ramp'!D14/INDEX(Assumptions!$D:$D,MATCH("Facilities / Admin (managed)",Assumptions!$B:$B,0)),0) -> 3 | E9: =ROUNDUP('HC Ramp'!E14/INDEX(Assumptions!$C:$C,MATCH("Facilities / Admin (managed)",Assumptions!$B:$B,0)),0) -> 5 | F9: =ROUNDUP('HC Ramp'!F14/INDEX(Assumptions!$C:$C,MATCH("Facilities / Admin (managed)",Assumptions!$B:$B,0)),0) -> 7 | G9: =ROUNDUP('HC Ramp'!G14/INDEX(Assumptions!$C:$C,MATCH("Facilities / Admin (managed)",Assumptions!$B:$B,0)),0) -> 8 | H9: =ROUNDUP('HC Ramp'!H14/INDEX(Assumptions!$C:$C,MATCH("Facilities / Admin (managed)",Assumptions!$B:$B,0)),0) -> 9
B10: Site Leadership + PMO HC | C10: 1 : 25 (SS) | D10: =ROUNDUP('HC Ramp'!D14/INDEX(Assumptions!$D:$D,MATCH("Site Leadership + PMO",Assumptions!$B:$B,0)),0) -> 5 | E10: =ROUNDUP('HC Ramp'!E14/INDEX(Assumptions!$C:$C,MATCH("Site Leadership + PMO",Assumptions!$B:$B,0)),0) -> 8 | F10: =ROUNDUP('HC Ramp'!F14/INDEX(Assumptions!$C:$C,MATCH("Site Leadership + PMO",Assumptions!$B:$B,0)),0) -> 12 | G10: =ROUNDUP('HC Ramp'!G14/INDEX(Assumptions!$C:$C,MATCH("Site Leadership + PMO",Assumptions!$B:$B,0)),0) -> 13 | H10: =ROUNDUP('HC Ramp'!H14/INDEX(Assumptions!$C:$C,MATCH("Site Leadership + PMO",Assumptions!$B:$B,0)),0) -> 15
B11: TOTAL Enabling HC | D11: =SUM(D6:D10) -> 27 | E11: =SUM(E6:E10) -> 48 | F11: =SUM(F6:F10) -> 75 | G11: =SUM(G6:G10) -> 83 | H11: =SUM(H6:H10) -> 92
B13: COST (INR Crore)
B14: HR Ops (generalist + TA) cost | D14: =D6*INDEX(Assumptions!$E:$E,MATCH("HR Ops (generalist + TA)",Assumptions!$B:$B,0))*(1+Assumptions!$C$8)^(1-1)/100 -> 1.4 | E14: =E6*INDEX(Assumptions!$E:$E,MATCH("HR Ops (generalist + TA)",Assumptions!$B:$B,0))*(1+Assumptions!$C$8)^(2-1)/100 -> 2.7216 | F14: =F6*INDEX(Assumptions!$E:$E,MATCH("HR Ops (generalist + TA)",Assumptions!$B:$B,0))*(1+Assumptions!$C$8)^(3-1)/100 -> 4.572288 | G14: =G6*INDEX(Assumptions!$E:$E,MATCH("HR Ops (generalist + TA)",Assumptions!$B:$B,0))*(1+Assumptions!$C$8)^(4-1)/100 -> 5.4671501 | H14: =H6*INDEX(Assumptions!$E:$E,MATCH("HR Ops (generalist + TA)",Assumptions!$B:$B,0))*(1+Assumptions!$C$8)^(5-1)/100 -> 6.4759274
B15: Finance Ops (AP/GL/Controllership) cost | D15: =D7*INDEX(Assumptions!$E:$E,MATCH("Finance Ops (AP/GL/Controllership)",Assumptions!$B:$B,0))*(1+Assumptions!$C$8)^(1-1)/100 -> 0.9 | E15: =E7*INDEX(Assumptions!$E:$E,MATCH("Finance Ops (AP/GL/Controllership)",Assumptions!$B:$B,0))*(1+Assumptions!$C$8)^(2-1)/100 -> 1.782 | F15: =F7*INDEX(Assumptions!$E:$E,MATCH("Finance Ops (AP/GL/Controllership)",Assumptions!$B:$B,0))*(1+Assumptions!$C$8)^(3-1)/100 -> 3.14928 | G15: =G7*INDEX(Assumptions!$E:$E,MATCH("Finance Ops (AP/GL/Controllership)",Assumptions!$B:$B,0))*(1+Assumptions!$C$8)^(4-1)/100 -> 3.779136 | H15: =H7*INDEX(Assumptions!$E:$E,MATCH("Finance Ops (AP/GL/Controllership)",Assumptions!$B:$B,0))*(1+Assumptions!$C$8)^(5-1)/100 -> 4.4896136
B16: IT Support / DevEx cost | D16: =D8*INDEX(Assumptions!$E:$E,MATCH("IT Support / DevEx",Assumptions!$B:$B,0))*(1+Assumptions!$C$8)^(1-1)/100 -> 0.48 | E16: =E8*INDEX(Assumptions!$E:$E,MATCH("IT Support / DevEx",Assumptions!$B:$B,0))*(1+Assumptions!$C$8)^(2-1)/100 -> 1.0368 | F16: =F8*INDEX(Assumptions!$E:$E,MATCH("IT Support / DevEx",Assumptions!$B:$B,0))*(1+Assumptions!$C$8)^(3-1)/100 -> 1.86624 | G16: =G8*INDEX(Assumptions!$E:$E,MATCH("IT Support / DevEx",Assumptions!$B:$B,0))*(1+Assumptions!$C$8)^(4-1)/100 -> 2.2170931 | H16: =H8*INDEX(Assumptions!$E:$E,MATCH("IT Support / DevEx",Assumptions!$B:$B,0))*(1+Assumptions!$C$8)^(5-1)/100 -> 2.6121388
B17: Facilities / Admin (managed) cost | D17: =D9*INDEX(Assumptions!$E:$E,MATCH("Facilities / Admin (managed)",Assumptions!$B:$B,0))*(1+Assumptions!$C$8)^(1-1)/100 -> 0.27 | E17: =E9*INDEX(Assumptions!$E:$E,MATCH("Facilities / Admin (managed)",Assumptions!$B:$B,0))*(1+Assumptions!$C$8)^(2-1)/100 -> 0.486 | F17: =F9*INDEX(Assumptions!$E:$E,MATCH("Facilities / Admin (managed)",Assumptions!$B:$B,0))*(1+Assumptions!$C$8)^(3-1)/100 -> 0.734832 | G17: =G9*INDEX(Assumptions!$E:$E,MATCH("Facilities / Admin (managed)",Assumptions!$B:$B,0))*(1+Assumptions!$C$8)^(4-1)/100 -> 0.90699264 | H17: =H9*INDEX(Assumptions!$E:$E,MATCH("Facilities / Admin (managed)",Assumptions!$B:$B,0))*(1+Assumptions!$C$8)^(5-1)/100 -> 1.1019961
B18: Site Leadership + PMO cost | D18: =D10*INDEX(Assumptions!$E:$E,MATCH("Site Leadership + PMO",Assumptions!$B:$B,0))*(1+Assumptions!$C$8)^(1-1)/100 -> 2.1 | E18: =E10*INDEX(Assumptions!$E:$E,MATCH("Site Leadership + PMO",Assumptions!$B:$B,0))*(1+Assumptions!$C$8)^(2-1)/100 -> 3.6288 | F18: =F10*INDEX(Assumptions!$E:$E,MATCH("Site Leadership + PMO",Assumptions!$B:$B,0))*(1+Assumptions!$C$8)^(3-1)/100 -> 5.878656 | G18: =G10*INDEX(Assumptions!$E:$E,MATCH("Site Leadership + PMO",Assumptions!$B:$B,0))*(1+Assumptions!$C$8)^(4-1)/100 -> 6.8780275 | H18: =H10*INDEX(Assumptions!$E:$E,MATCH("Site Leadership + PMO",Assumptions!$B:$B,0))*(1+Assumptions!$C$8)^(5-1)/100 -> 8.5710804
B19: TOTAL Back-office cost (Crore) | D19: =SUM(D14:D18) -> 5.15 | E19: =SUM(E14:E18) -> 9.6552 | F19: =SUM(F14:F18) -> 16.201296 | G19: =SUM(G14:G18) -> 19.248399 | H19: =SUM(H14:H18) -> 23.250756

Sheet Total Cost Summary
B2: Total 5-year GCC cost — Recommended scenario (Bengaluru + Pune)
B3: All figures INR Crore. GBP conversion at 1 GBP = 105 INR.
B5: Cost head | C5: Year 1 | D5: Year 2 | E5: Year 3 | F5: Year 4 | G5: Year 5 | H5: 5-yr Total
B6: Core Talent Cost | C6: ='Core Talent Cost'!D14 -> 40.998 | D6: ='Core Talent Cost'!E14 -> 105.516 | E6: ='Core Talent Cost'!F14 -> 176.425 | F6: ='Core Talent Cost'!G14 -> 211.06223 | G6: ='Core Talent Cost'!H14 -> 249.31504 | H6: =SUM(C6:G6) -> 783.31627
B7: Infra & Facilities (opex) | C7: ='Infra & Facilities'!D18 -> 3.8947737 | D7: ='Infra & Facilities'!E18 -> 8.3814962 | E7: ='Infra & Facilities'!F18 -> 12.509482 | F7: ='Infra & Facilities'!G18 -> 14.052846 | G7: ='Infra & Facilities'!H18 -> 15.622437 | H7: =SUM(C7:G7) -> 54.461035
B8: Infra Setup (one-time) | C8: ='Infra & Facilities'!D20 -> 25.8 | D8: ='Infra & Facilities'!E20 -> 10.5 | E8: ='Infra & Facilities'!F20 -> 0 | F8: ='Infra & Facilities'!G20 -> 0 | G8: ='Infra & Facilities'!H20 -> 0 | H8: =SUM(C8:G8) -> 36.3
B9: Back-office (Enabling) | C9: ='Back-office (Ratios)'!D19 -> 5.15 | D9: ='Back-office (Ratios)'!E19 -> 9.6552 | E9: ='Back-office (Ratios)'!F19 -> 16.201296 | F9: ='Back-office (Ratios)'!G19 -> 19.248399 | G9: ='Back-office (Ratios)'!H19 -> 23.250756 | H9: =SUM(C9:G9) -> 73.505652
B10: Governance & Compliance (5%) | C10: =SUM(C6:C9)*0.05 -> 3.7921387 | D10: =SUM(D6:D9)*0.05 -> 6.7026348 | E10: =SUM(E6:E9)*0.05 -> 10.256789 | F10: =SUM(F6:F9)*0.05 -> 12.218174 | G10: =SUM(G6:G9)*0.05 -> 14.409412 | H10: =SUM(C10:G10) -> 47.379148
B11: TOTAL GCC Cost (Crore) | C11: =SUM(C6:C10) -> 79.634912 | D11: =SUM(D6:D10) -> 140.75533 | E11: =SUM(E6:E10) -> 215.39257 | F11: =SUM(F6:F10) -> 256.58164 | G11: =SUM(G6:G10) -> 302.59765 | H11: =SUM(C11:G11) -> 994.9621
B12: TOTAL in GBP million | C12: =C11*10/Assumptions!$C$6 -> 7.5842774 | D12: =D11*10/Assumptions!$C$6 -> 13.40527 | E12: =E11*10/Assumptions!$C$6 -> 20.513578 | F12: =F11*10/Assumptions!$C$6 -> 24.436347 | G12: =G11*10/Assumptions!$C$6 -> 28.818824 | H12: =SUM(C12:G12) -> 94.758296
B14: Total FTE (Core) | C14: ='HC Ramp'!D14 -> 173 | D14: ='HC Ramp'!E14 -> 439 | E14: ='HC Ramp'!F14 -> 694 | F14: ='HC Ramp'!G14 -> 771 | G14: ='HC Ramp'!H14 -> 845
B15: Fully-loaded cost / FTE (GBP) | C15: =IF(C14=0,0,C12*1000000/C14) -> 43839.754 | D15: =IF(D14=0,0,D12*1000000/D14) -> 30535.922 | E15: =IF(E14=0,0,E12*1000000/E14) -> 29558.469 | F15: =IF(F14=0,0,F12*1000000/F14) -> 31694.354 | G15: =IF(G14=0,0,G12*1000000/G14) -> 34105.117
B17: UK / IE BASELINE COMPARISON
B18: Metric | C18: Year 1 | D18: Year 2 | E18: Year 3 | F18: Year 4 | G18: Year 5 | H18: 5-yr
B19: Equivalent UK cost / FTE (GBP) | C19: 78000 | D19: 80730 | E19: 83556 | F19: 86480 | G19: 89507
B20: UK equivalent total (GBP mn) | C20: =C14*C19/1000000 -> 13.494 | D20: =D14*D19/1000000 -> 35.44047 | E20: =E14*E19/1000000 -> 57.987864 | F20: =F14*F19/1000000 -> 66.67608 | G20: =G14*G19/1000000 -> 75.633415 | H20: =SUM(C20:G20) -> 249.23183
B21: GCC cost (GBP mn) | C21: =C12 -> 7.5842774 | D21: =D12 -> 13.40527 | E21: =E12 -> 20.513578 | F21: =F12 -> 24.436347 | G21: =G12 -> 28.818824 | H21: =SUM(C21:G21) -> 94.758296
B22: SAVINGS (GBP mn) | C22: =C20-C21 -> 5.9097226 | D22: =D20-D21 -> 22.0352 | E22: =E20-E21 -> 37.474286 | F22: =F20-F21 -> 42.239733 | G22: =G20-G21 -> 46.814591 | H22: =SUM(C22:G22) -> 154.47353
B23: Savings % | C23: =IF(C20=0,0,C22/C20) -> 0.43795188 | D23: =IF(D20=0,0,D22/D20) -> 0.62175249 | E23: =IF(E20=0,0,E22/E20) -> 0.64624361 | F23: =IF(F20=0,0,F22/F20) -> 0.63350654 | G23: =IF(G20=0,0,G22/G20) -> 0.61896704 | H23: =IF(H20=0,0,H22/H20) -> 0.61979858

Sheet Scenario Comparison
B2: Scenario comparison — 4 city configurations
B3: Cost figures reflect 5-year steady-state Year 3 run-rate. Numbers directional — key deltas explained in Synthesis Notes.
B5: Dimension | C5: Bengaluru only | D5: Hyderabad only | E5: Pune only | F5: Blr + Pune (Rec.) | G5: Winner
B6: Y3 Total cost (INR Crore) | C6: 205 | D6: 186 | E6: 188 | F6: 195 | G6: Hyd
B7: Y3 Savings vs UK (%) | C7: 39% | D7: 44% | E7: 43% | F7: 41% | G7: Hyd
B8: 5-yr NPV cost (Crore) | C8: 918 | D8: 842 | E8: 855 | F8: 878 | G8: Hyd
B9: Talent quality (index) | C9: 96 | D9: 87 | E9: 82 | F9: 94 | G9: Blr
B10: Leadership pool (score /5) | C10: 5 | D10: 3 | E10: 2 | F10: 5 | G10: Blr / Rec
B11: Attrition Y3 (%) | C11: 14.2% | D11: 16.1% | E11: 12.4% | F11: 13.6% | G11: Rec
B12: Speed to boots-on-ground (mo) | C12: 6 | D12: 4.5 | E12: 5.5 | F12: 6 | G12: Hyd
B13: Execution risk (Y1) | C13: Med | D13: Med | E13: Med | F13: Med (single-city Y1) | G13: =
B14: Board-narrative fit | C14: Strong | D14: Weaker | E14: Weaker | F14: Strongest | G14: Rec
B15: Scalability to 1,500 FTE by Y7 | C15: Yes | D15: Tight | E15: Tight | F15: Yes | G15: Blr / Rec
B17: ANSR Recommendation: Bengaluru primary hub (Y1) + Pune spoke (Y2+) for Finance Ops & HR CoE
B18: Hyderabad shows the lowest headline cost, but the delta over the recommended scenario is only ~3% NPV — which is much smaller than the capability and leadership-pool trade-off. Bengaluru is the deepest Tech/Data market and the only city with a credible MD-grade leadership pool. Splitting Finance Ops and HR Ops CoE to Pune from Year 2 captures ~90% of the Pune cost advantage without paying the Year-1 execution tax of a two-city build. On a risk-adjusted 5-year view, the recommended scenario wins.
